(dp1
S'output'
p2
S"<type 'exceptions.ValueError'> Failed to create Point instance from string: unknown format."
p3
sS'layer'
p4
S'/home/utahgroup/web2py/applications/welcome/controllers/mappage.py'
p5
sS'code'
p6
S'<code object <module> at 0x7f0c177cac30, file "/home/utahgroup/web2py/applications/welcome/controllers/mappage.py", line 3>'
p7
sS'snapshot'
p8
(dp9
sS'traceback'
p10
S'Traceback (most recent call last):\n  File "/home/utahgroup/web2py/gluon/restricted.py", line 219, in restricted\n    exec(ccode, environment)\n  File "/home/utahgroup/web2py/applications/welcome/controllers/mappage.py", line 24, in <module>\n  File "/home/utahgroup/web2py/gluon/globals.py", line 421, in <lambda>\n    self._caller = lambda f: f()\n  File "/home/utahgroup/web2py/applications/welcome/controllers/mappage.py", line 17, in map\n    if geopy.distance.vincenty(coords_start, rows[count][4] ).mi < 100:\n  File "/usr/local/lib/python2.7/dist-packages/geopy/distance.py", line 496, in __init__\n    super(vincenty, self).__init__(*args, **kwargs)\n  File "/usr/local/lib/python2.7/dist-packages/geopy/distance.py", line 164, in __init__\n    kilometers += self.measure(a, b)\n  File "/usr/local/lib/python2.7/dist-packages/geopy/distance.py", line 516, in measure\n    a, b = Point(a), Point(b)\n  File "/usr/local/lib/python2.7/dist-packages/geopy/point.py", line 162, in __new__\n    return cls.from_string(arg)\n  File "/usr/local/lib/python2.7/dist-packages/geopy/point.py", line 396, in from_string\n    "Failed to create Point instance from string: unknown format."\nValueError: Failed to create Point instance from string: unknown format.\n'
p11
s.